### 回调

异步编程依托于回调来实现。



### 代码设计模式



#### “函数返回值”

一个函数的输出作为另一个函数的输入是很常见的需求。

```js
// 同步
var output = fn1(fn2('input'));

// 异步
// 套得太多了很容易写出>形状的代码
fn2('input', function (output2) {
    fn1(output2, function (output1) {
        // Do something.
    });
});
```



#### “遍历数组”

在遍历数组时，使用某个函数依次对数据成员做一些处理也是常见的需求。

```js
// 同步
for (let i = 0; i < len; ++i) {
    arr[i] = sync(arr[i]);
}

// 异步
(function next(i, len, cb) {
	if (i < len) {
		async(arr[i], val => {
			arr[i] = val
			next(i + 1, len, cb)
		})
	} else {
		cb && cb()
	}
})(0, arr.length, () => {
	// 所有元素处理之后的回调
})

// 要求能够并行
((count, len, cb) => {
    for (let i = 0; i < len; ++i) {
        async(arr[i], val => {
            arr[i] = val
            if (++count === len) {
                cb && cb()
            }
        })
    }
})(0, arr.length, () => {
    // 所有元素处理之后的回调
})
```



#### “异常处理”

`JS--catch`块只能用于捕获同步代码抛出的异常。对于异步代码，我们需要在异常冒泡到断点之前用`try`语句把异常捕获住，并通过回调函数传递被捕获的异常。

```js
function async(fn, callback) {
    // Code execution path breaks here.
    // 按照这种方式来处理异常，与NodeJS的设计风格保持一致。
    setTimeout(()　=> {
        try {
            callback(null, fn());
        } catch (err) {
            
            callback(err);
        }
    }, 0);
}

async(null, (err, data) => {
    // 在NodeJS中，几乎所有异步API都按照以上方式设计，回调函数中第一个参数都是err
    if (err) {
        console.log('Error: %s', err.message);
    } else {
        // Do something.
    }
});

```

但是...试想如下情景

```js
function main(callback) {
    // Do something.
    asyncA(function (err, data) {
        if (err) {
            callback(err);
        } else {
            // Do something
            asyncB(function (err, data) {
                if (err) {
                    callback(err);
                } else {
                    // Do something
                    asyncC(function (err, data) {
                        if (err) {
                            callback(err);
                        } else {
                            // Do something
                            callback(null);
                        }
                    });
                }
            });
        }
    });
}

main(function (err) {
    if (err) {
        // Deal with exception.
    }
});
```

NodeJS的最大卖点最后变成这个样子，那就没人愿意用NodeJS了，因此接下来会介绍NodeJS提供的一些解决方案。



### 域（Domain）

> 域：简单的讲，一个域就是一个JS运行环境，在一个运行环境中，如果一个异常没有被捕获，将作为一个全局异常被抛出。



```js
// NodeJS通过`process`对象提供了捕获全局异常的方法
// 实例代码
process.on('uncaughtException', err => {
    console.log('Error: %s', err.message);
});

setTimeout(fn => {
    fn();
});

// 输出
// Error: undefined is not a function
```



虽然全局异常有个地方可以捕获了，但是对于大多数异常，我们希望尽早捕获，并根据结果决定代码的执行路径。我们用以下HTTP服务器代码作为例子：

```js
// 这里采用了使用回调函数传递异常的方案
// 方案缺点：回调嵌套严重
function async(req, callback) {
    // Do something.
    asyncA(res, (err, data) => {
        if (err) {
            callback(err);
        } else {
            // Do something
            asyncB(req, (err, data) => {
                if (err) {
                    callback(err);
                } else {
                    // Do something
                    asyncC(req, (err, data) => {
                        if (err) {
                            callback(err);
                        } else {
                            // Do something
                            callback(null, data);
                        }
                    });
                }
            });
        }
    });
}

http.createServer((req, res) => {
    async(req, (err, data) => {
        if (err) {
            res.writeHead(500);
            res.end();
        } else {
            res.writeHead(200);
            res.end(data);
        }
    });
});
```



> NodeJS提供的`domain`模块，可以简化异步代码的异常处理。

使用 domain：

```js
function async(req, cb) {
  asyncA(req, data => {
    // Do something
    asyncB(req, data => {
      // Do something
      asyncC(req, data => {
        // Do something
        cb(data)
      })
    })
  })
}

http.createServer((req, res) => {
  const d = domain.create()

  d.on('error', () => {
    res.writeHead(500)
    res.end()
  })

  d.run(() => {
    async(req, data => {
      res.writeHead(200)
      res.end(data)
    })
  })
})
```



#### 注意陷阱

使用`uncaughtException`或`domain`捕获异常，代码执行路径里涉及到了C/C++部分的代码时，如果不能确定是否会导致内存泄漏等问题，最好在处理完异常后重启程序比较妥当。

而使用`try`语句捕获异常时一般捕获到的都是JS本身的异常，不用担心上诉问题。